Workbook

Sheet Correção
A1: IDADE/RESPONDENTE: | B1: escolar
A2: SEXO: | B2: M
B4: ITENS | C4: RESPOSTA | D4: PONTUAÇÃO | H4: ESCORE BRUTO | I4: ESCORE T
B5: 1 | C5: 1 | D5: =IF(C5=1,0,IF(C5=2,1,IF(C5=3,2,IF(C5=4,3,)))) -> 0 | G5: TOTAL | H5: =SUM(D5:D69) -> 51 | I5: =IF(AND(B2="M",B1="escolar"),LOOKUP(H5,'Norma escolar (masculino)'!A5:A200,'Norma escolar (masculino)'!B5:B200),IF(AND(B2="F",B1="escolar"),LOOKUP(H5,'Norma escolar (feminino)'!A5:A200,'Norma escolar (feminino)'!B5:B200),IF(AND(B2=0,B1="pre"),LOOKUP(H5,'Norma pré-escolar'!A5:A200,'Norma pré-escolar'!B5:B200),IF(AND(B2=0,B1="adulto a"),LOOKUP(H5,'Norma adulto autorrelato'!A5:A200,'Norma adulto autorrelato'!B5:B200),IF(AND(B2=0,B1="adulto h"),LOOKUP(H5,'Norma adulto hetero'!A5:A200,'Norma adulto hetero'!B5:B200)))))) -> 53
B6: 2 | C6: 1 | D6: =IF(C6=1,0,IF(C6=2,1,IF(C6=3,2,IF(C6=4,3,)))) -> 0 | G6: PERCEPÇÃO SOCIAL | H6: =SUM(D6,D11,D29,D36,D49,D56,D58,D60) -> 12 | I6: =IF(AND(B2="M",B1="escolar"),LOOKUP(H6,'Norma escolar (masculino)'!D5:D29,'Norma escolar (masculino)'!E5:E29),IF(AND(B2="F",B1="escolar"),LOOKUP(H6,'Norma escolar (feminino)'!D5:D29,'Norma escolar (feminino)'!E5:E29),IF(AND(B2=0,B1="pre"),LOOKUP(H6,'Norma pré-escolar'!D5:D29,'Norma pré-escolar'!E5:E29),IF(AND(B2=0,B1="adulto a"),LOOKUP(H6,'Norma adulto autorrelato'!D5:D29,'Norma adulto autorrelato'!E5:E29),IF(AND(B2=0,B1="adulto h"),LOOKUP(H6,'Norma adulto hetero'!D5:D29,'Norma adulto hetero'!E5:E29)))))) -> 60
B7: 3 | C7: 1 | D7: =IF(C7=1,3,IF(C7=2,2,IF(C7=3,1,IF(C7=4,0,)))) -> 3 | G7: COGNIÇÃO SOCIAL | H7: =SUM(D9,D14,D19,D21,D34,D44,D46,D48,D52,D62,D63,D66) -> 12 | I7: =IF(AND(B2="M",B1="escolar"),LOOKUP(H7,'Norma escolar (masculino)'!G5:G41,'Norma escolar (masculino)'!H5:H41),IF(AND(B2="F",B1="escolar"),LOOKUP(H7,'Norma escolar (feminino)'!G5:G41,'Norma escolar (feminino)'!H5:H41),IF(AND(B2=0,B1="pre"),LOOKUP(H7,'Norma pré-escolar'!G5:G41,'Norma pré-escolar'!H5:H41),IF(AND(B2=0,B1="adulto a"),LOOKUP(H7,'Norma adulto autorrelato'!G5:G41,'Norma adulto autorrelato'!H5:H41),IF(AND(B2=0,B1="adulto h"),LOOKUP(H7,'Norma adulto hetero'!G5:G41,'Norma adulto hetero'!H5:H41)))))) -> 54
B8: 4 | C8: 1 | D8: =IF(C8=1,0,IF(C8=2,1,IF(C8=3,2,IF(C8=4,3,)))) -> 0 | G8: COMUNICAÇÃO SOCIAL | H8: =SUM(D16,D17,D20,D22,D23,D25,D26,D30,D37,D39,D40,D41,D42,D45,D50,D51,D55,D57,D59,D61,D64,D65) -> 18 | I8: =IF(AND(B2="M",B1="escolar"),LOOKUP(H8,'Norma escolar (masculino)'!J5:J71,'Norma escolar (masculino)'!K5:K71),IF(AND(B2="F",B1="escolar"),LOOKUP(H8,'Norma escolar (feminino)'!J5:J71,'Norma escolar (feminino)'!K5:K71),IF(AND(B2=0,B1="pre"),LOOKUP(H8,'Norma pré-escolar'!J5:J71,'Norma pré-escolar'!K5:K71),IF(AND(B2=0,B1="adulto a"),LOOKUP(H8,'Norma adulto autorrelato'!J5:J71,'Norma adulto autorrelato'!K5:K71),IF(AND(B2=0,B1="adulto h"),LOOKUP(H8,'Norma adulto hetero'!J5:J71,'Norma adulto hetero'!K5:K71)))))) -> 54
B9: 5 | C9: 1 | D9: =IF(C9=1,0,IF(C9=2,1,IF(C9=3,2,IF(C9=4,3,)))) -> 0 | G9: MOTIVAÇÃO SOCIAL | H9: =SUM(D5,D7,D10,D13,D15,D27,D31,D38,D47,D68,D69) -> 9 | I9: =IF(AND(B2="M",B1="escolar"),LOOKUP(H9,'Norma escolar (masculino)'!M5:M38,'Norma escolar (masculino)'!N5:N38),IF(AND(B2="F",B1="escolar"),LOOKUP(H9,'Norma escolar (feminino)'!M5:M38,'Norma escolar (feminino)'!N5:N38),IF(AND(B2=0,B1="pre"),LOOKUP(H9,'Norma pré-escolar'!M5:M38,'Norma pré-escolar'!N5:N38),IF(AND(B2=0,B1="adulto a"),LOOKUP(H9,'Norma adulto autorrelato'!M5:M38,'Norma adulto autorrelato'!N5:N38),IF(AND(B2=0,B1="adulto h"),LOOKUP(H9,'Norma adulto hetero'!M5:M38,'Norma adulto hetero'!N5:N38)))))) -> 51
B10: 6 | C10: 1 | D10: =IF(C10=1,0,IF(C10=2,1,IF(C10=3,2,IF(C10=4,3,)))) -> 0 | G10: PADRÕES RESTRITOS E REPETITIVOS | H10: =SUM(D8,D12,D18,D24,D28,D32,D33,D35,D43,D53,D54,D67) -> 0 | I10: =IF(AND(B2="M",B1="escolar"),LOOKUP(H10,'Norma escolar (masculino)'!P5:P41,'Norma escolar (masculino)'!Q5:Q41),IF(AND(B2="F",B1="escolar"),LOOKUP(H10,'Norma escolar (feminino)'!P5:P41,'Norma escolar (feminino)'!Q5:Q41),IF(AND(B2=0,B1="pre"),LOOKUP(H10,'Norma pré-escolar'!P5:P41,'Norma pré-escolar'!Q5:Q41),IF(AND(B2=0,B1="adulto a"),LOOKUP(H10,'Norma adulto autorrelato'!P5:P41,'Norma adulto autorrelato'!Q5:Q41),IF(AND(B2=0,B1="adulto h"),LOOKUP(H10,'Norma adulto hetero'!P5:P41,'Norma adulto hetero'!Q5:Q41)))))) -> 29
B11: 7 | C11: 1 | D11: =IF(C11=1,3,IF(C11=2,2,IF(C11=3,1,IF(C11=4,0,)))) -> 3 | G11: COMUNICAÇÃO E INTERAÇÃO SOCIAL | H11: =SUM(H6:H9) -> 51 | I11: =IF(AND(B2="M",B1="escolar"),LOOKUP(H11,'Norma escolar (masculino)'!S5:S164,'Norma escolar (masculino)'!T5:T164),IF(AND(B2="F",B1="escolar"),LOOKUP(H11,'Norma escolar (feminino)'!S5:S164,'Norma escolar (feminino)'!T5:T164),IF(AND(B2=0,B1="pre"),LOOKUP(H11,'Norma pré-escolar'!S5:S164,'Norma pré-escolar'!T5:T164),IF(AND(B2=0,B1="adulto a"),LOOKUP(H11,'Norma adulto autorrelato'!S5:S164,'Norma adulto autorrelato'!T5:T164),IF(AND(B2=0,B1="adulto h"),LOOKUP(H11,'Norma adulto hetero'!S5:S164,'Norma adulto hetero'!T5:T164)))))) -> 54
B12: 8 | C12: 1 | D12: =IF(C12=1,0,IF(C12=2,1,IF(C12=3,2,IF(C12=4,3,)))) -> 0
B13: 9 | C13: 1 | D13: =IF(C13=1,0,IF(C13=2,1,IF(C13=3,2,IF(C13=4,3,)))) -> 0
B14: 10 | C14: 1 | D14: =IF(C14=1,0,IF(C14=2,1,IF(C14=3,2,IF(C14=4,3,)))) -> 0
B15: 11 | C15: 1 | D15: =IF(C15=1,3,IF(C15=2,2,IF(C15=3,1,IF(C15=4,0,)))) -> 3
B16: 12 | C16: 1 | D16: =IF(C16=1,3,IF(C16=2,2,IF(C16=3,1,IF(C16=4,0,)))) -> 3
B17: 13 | C17: 1 | D17: =IF(C17=1,0,IF(C17=2,1,IF(C17=3,2,IF(C17=4,3,)))) -> 0
B18: 14 | C18: 1 | D18: =IF(C18=1,0,IF(C18=2,1,IF(C18=3,2,IF(C18=4,3,)))) -> 0
B19: 15 | C19: 1 | D19: =IF(C19=1,3,IF(C19=2,2,IF(C19=3,1,IF(C19=4,0,)))) -> 3
B20: 16 | C20: 1 | D20: =IF(C20=1,0,IF(C20=2,1,IF(C20=3,2,IF(C20=4,3,)))) -> 0
B21: 17 | C21: 1 | D21: =IF(C21=1,3,IF(C21=2,2,IF(C21=3,1,IF(C21=4,0,)))) -> 3
B22: 18 | C22: 1 | D22: =IF(C22=1,0,IF(C22=2,1,IF(C22=3,2,IF(C22=4,3,)))) -> 0
B23: 19 | C23: 1 | D23: =IF(C23=1,0,IF(C23=2,1,IF(C23=3,2,IF(C23=4,3,)))) -> 0
B24: 20 | C24: 1 | D24: =IF(C24=1,0,IF(C24=2,1,IF(C24=3,2,IF(C24=4,3,)))) -> 0
B25: 21 | C25: 1 | D25: =IF(C25=1,3,IF(C25=2,2,IF(C25=3,1,IF(C25=4,0,)))) -> 3
B26: 22 | C26: 1 | D26: =IF(C26=1,3,IF(C26=2,2,IF(C26=3,1,IF(C26=4,0,)))) -> 3
B27: 23 | C27: 1 | D27: =IF(C27=1,0,IF(C27=2,1,IF(C27=3,2,IF(C27=4,3,)))) -> 0
B28: 24 | C28: 1 | D28: =IF(C28=1,0,IF(C28=2,1,IF(C28=3,2,IF(C28=4,3,)))) -> 0
B29: 25 | C29: 1 | D29: =IF(C29=1,0,IF(C29=2,1,IF(C29=3,2,IF(C29=4,3,)))) -> 0
B30: 26 | C30: 1 | D30: =IF(C30=1,3,IF(C30=2,2,IF(C30=3,1,IF(C30=4,0,)))) -> 3
B31: 27 | C31: 1 | D31: =IF(C31=1,0,IF(C31=2,1,IF(C31=3,2,IF(C31=4,3,)))) -> 0
B32: 28 | C32: 1 | D32: =IF(C32=1,0,IF(C32=2,1,IF(C32=3,2,IF(C32=4,3,)))) -> 0
B33: 29 | C33: 1 | D33: =IF(C33=1,0,IF(C33=2,1,IF(C33=3,2,IF(C33=4,3,)))) -> 0
B34: 30 | C34: 1 | D34: =IF(C34=1,0,IF(C34=2,1,IF(C34=3,2,IF(C34=4,3,)))) -> 0
B35: 31 | C35: 1 | D35: =IF(C35=1,0,IF(C35=2,1,IF(C35=3,2,IF(C35=4,3,)))) -> 0
B36: 32 | C36: 1 | D36: =IF(C36=1,3,IF(C36=2,2,IF(C36=3,1,IF(C36=4,0,)))) -> 3
B37: 33 | C37: 1 | D37: =IF(C37=1,0,IF(C37=2,1,IF(C37=3,2,IF(C37=4,3,)))) -> 0
B38: 34 | C38: 1 | D38: =IF(C38=1,0,IF(C38=2,1,IF(C38=3,2,IF(C38=4,3,)))) -> 0
B39: 35 | C39: 1 | D39: =IF(C39=1,0,IF(C39=2,1,IF(C39=3,2,IF(C39=4,3,)))) -> 0
B40: 36 | C40: 1 | D40: =IF(C40=1,0,IF(C40=2,1,IF(C40=3,2,IF(C40=4,3,)))) -> 0
B41: 37 | C41: 1 | D41: =IF(C41=1,0,IF(C41=2,1,IF(C41=3,2,IF(C41=4,3,)))) -> 0
...

Sheet Norma pré-escolar
A1: PRÉ-ESCOLAR | D1: 2;6-4;6
A3: ESCORE TOTAL | D3: PERCEPÇÃO SOCIAL | G3: COGNIÇÃO SOCIAL | J3: COMUNICAÇÃO SOCIAL | M3: MOTIVAÇÃO SOCIAL | P3: PADRÕES RESTRITOS E REPETITIVOS | S3: COMUNICAÇÃO E INTERAÇÃO SOCIAL
A4: EB | B4: T | D4: EB | E4: T | G4: EB | H4: T | J4: EB | K4: T | M4: EB | N4: T | P4: EB | Q4: T | S4: EB | T4: T
A5: 0 | B5: 22 | D5: 0 | E5: 28 | G5: 0 | H5: 25 | J5: 0 | K5: 25 | M5: 0 | N5: 22 | P5: 0 | Q5: 33 | S5: 0 | T5: 25
A6: 1 | B6: 22 | D6: 1 | E6: 33 | G6: 1 | H6: 30 | J6: 1 | K6: 25 | M6: 1 | N6: 31 | P6: 1 | Q6: 39 | S6: 1 | T6: 25
A7: 2 | B7: 22 | D7: 2 | E7: 37 | G7: 2 | H7: 34 | J7: 2 | K7: 25 | M7: 2 | N7: 35 | P7: 2 | Q7: 44 | S7: 2 | T7: 25
A8: 3 | B8: 22 | D8: 3 | E8: 41 | G8: 3 | H8: 38 | J8: 3 | K8: 29 | M8: 3 | N8: 37 | P8: 3 | Q8: 48 | S8: 3 | T8: 25
A9: 4 | B9: 22 | D9: 4 | E9: 44 | G9: 4 | H9: 42 | J9: 4 | K9: 33 | M9: 4 | N9: 41 | P9: 4 | Q9: 50 | S9: 4 | T9: 25
A10: 5 | B10: 22 | D10: 5 | E10: 48 | G10: 5 | H10: 44 | J10: 5 | K10: 37 | M10: 5 | N10: 44 | P10: 5 | Q10: 51 | S10: 5 | T10: 25
A11: 6 | B11: 22 | D11: 6 | E11: 51 | G11: 6 | H11: 47 | J11: 6 | K11: 40 | M11: 6 | N11: 46 | P11: 6 | Q11: 53 | S11: 6 | T11: 25
A12: 7 | B12: 22 | D12: 7 | E12: 53 | G12: 7 | H12: 48 | J12: 7 | K12: 42 | M12: 7 | N12: 48 | P12: 7 | Q12: 55 | S12: 7 | T12: 25
A13: 8 | B13: 22 | D13: 8 | E13: 55 | G13: 8 | H13: 50 | J13: 8 | K13: 45 | M13: 8 | N13: 51 | P13: 8 | Q13: 56 | S13: 8 | T13: 28
A14: 9 | B14: 26 | D14: 9 | E14: 57 | G14: 9 | H14: 52 | J14: 9 | K14: 47 | M14: 9 | N14: 53 | P14: 9 | Q14: 57 | S14: 9 | T14: 29
A15: 10 | B15: 26 | D15: 10 | E15: 59 | G15: 10 | H15: 54 | J15: 10 | K15: 48 | M15: 10 | N15: 55 | P15: 10 | Q15: 58 | S15: 10 | T15: 29
A16: 11 | B16: 29 | D16: 11 | E16: 60 | G16: 11 | H16: 55 | J16: 11 | K16: 50 | M16: 11 | N16: 56 | P16: 11 | Q16: 59 | S16: 11 | T16: 30
... A29: 24 | B29: 43 | D29: 24 | E29: 75 | G29: 24 | H29: 67 | J29: 24 | K29: 60 | M29: 24 | N29: 68 | P29: 24 | Q29: 67 | S29: 24 | T29: 45
A30: 25 | B30: 43 | G30: 25 | H30: 68 | J30: 25 | K30: 60 | M30: 25 | N30: 70 | P30: 25 | Q30: 67 | S30: 25 | T30: 46
A31: 26 | B31: 44 | G31: 26 | H31: 68 | J31: 26 | K31: 60 | M31: 26 | N31: 72 | P31: 26 | Q31: 67 | S31: 26 | T31: 46
A32: 27 | B32: 45 | G32: 27 | H32: 68 | J32: 27 | K32: 60 | M32: 27 | N32: 74 | P32: 27 | Q32: 69 | S32: 27 | T32: 47
A33: 28 | B33: 46 | G33: 28 | H33: 70 | J33: 28 | K33: 61 | M33: 28 | N33: 78 | P33: 28 | Q33: 70 | S33: 28 | T33: 48
A34: 29 | B34: 46 | G34: 29 | H34: 75 | J34: 29 | K34: 61 | M34: 29 | N34: 78 | P34: 29 | Q34: 70 | S34: 29 | T34: 48
A35: 30 | B35: 47 | G35: 30 | H35: 75 | J35: 30 | K35: 62 | M35: 30 | N35: 78 | P35: 30 | Q35: 70 | S35: 30 | T35: 49
A36: 31 | B36: 47 | G36: 31 | H36: 75 | J36: 31 | K36: 62 | M36: 31 | N36: 78 | P36: 31 | Q36: 72 | S36: 31 | T36: 49
A37: 32 | B37: 48 | G37: 32 | H37: 75 | J37: 32 | K37: 63 | M37: 32 | N37: 78 | P37: 32 | Q37: 74 | S37: 32 | T37: 50
A38: 33 | B38: 49 | G38: 33 | H38: 75 | J38: 33 | K38: 64 | M38: 33 | N38: 78 | P38: 33 | Q38: 74 | S38: 33 | T38: 51
A39: 34 | B39: 49 | G39: 34 | H39: 75 | J39: 34 | K39: 64 | P39: 34 | Q39: 78 | S39: 34 | T39: 51
A40: 35 | B40: 50 | G40: 35 | H40: 75 | J40: 35 | K40: 64 | P40: 35 | Q40: 78 | S40: 35 | T40: 52
A41: 36 | B41: 50 | G41: 36 | H41: 75 | J41: 36 | K41: 65 | P41: 36 | Q41: 78 | S41: 36 | T41: 52
A42: 37 | B42: 51 | J42: 37 | K42: 65 | S42: 37 | T42: 53
A43: 38 | B43: 51 | J43: 38 | K43: 66 | S43: 38 | T43: 54
A44: 39 | B44: 52 | J44: 39 | K44: 67 | S44: 39 | T44: 54
A45: 40 | B45: 52 | J45: 40 | K45: 67 | S45: 40 | T45: 54
A46: 41 | B46: 52 | J46: 41 | K46: 68 | S46: 41 | T46: 55
A47: 42 | B47: 53 | J47: 42 | K47: 69 | S47: 42 | T47: 55
A48: 43 | B48: 53 | J48: 43 | K48: 69 | S48: 43 | T48: 55
A49: 44 | B49: 54 | J49: 44 | K49: 69 | S49: 44 | T49: 56
A50: 45 | B50: 54 | J50: 45 | K50: 70 | S50: 45 | T50: 56
A51: 46 | B51: 55 | J51: 46 | K51: 70 | S51: 46 | T51: 56
A52: 47 | B52: 55 | J52: 47 | K52: 70 | S52: 47 | T52: 57
A53: 48 | B53: 55 | J53: 48 | K53: 71 | S53: 48 | T53: 57
...

Sheet Norma escolar (masculino)
A1: ESCOLAR MASCULINO | D1: 3;11-19
A3: ESCORE TOTAL | D3: PERCEPÇÃO SOCIAL | G3: COGNIÇÃO SOCIAL | J3: COMUNICAÇÃO SOCIAL | M3: MOTIVAÇÃO SOCIAL | P3: PADRÕES RESTRITOS E REPETITIVOS | S3: COMUNICAÇÃO E INTERAÇÃO SOCIAL
A4: EB | B4: T | D4: EB | E4: T | G4: EB | H4: T | J4: EB | K4: T | M4: EB | N4: T | P4: EB | Q4: T | S4: EB | T4: T
A5: 0 | B5: 27 | D5: 0 | E5: 29 | G5: 0 | H5: 27 | J5: 0 | K5: 25 | M5: 0 | N5: 29 | P5: 0 | Q5: 29 | S5: 0 | T5: 27
A6: 1 | B6: 27 | D6: 1 | E6: 33 | G6: 1 | H6: 31 | J6: 1 | K6: 25 | M6: 1 | N6: 29 | P6: 1 | Q6: 34 | S6: 1 | T6: 27
A7: 2 | B7: 27 | D7: 2 | E7: 36 | G7: 2 | H7: 33 | J7: 2 | K7: 25 | M7: 2 | N7: 33 | P7: 2 | Q7: 41 | S7: 2 | T7: 27
A8: 3 | B8: 27 | D8: 3 | E8: 39 | G8: 3 | H8: 36 | J8: 3 | K8: 25 | M8: 3 | N8: 35 | P8: 3 | Q8: 45 | S8: 3 | T8: 27
A9: 4 | B9: 27 | D9: 4 | E9: 42 | G9: 4 | H9: 40 | J9: 4 | K9: 32 | M9: 4 | N9: 40 | P9: 4 | Q9: 46 | S9: 4 | T9: 27
A10: 5 | B10: 27 | D10: 5 | E10: 45 | G10: 5 | H10: 42 | J10: 5 | K10: 36 | M10: 5 | N10: 43 | P10: 5 | Q10: 48 | S10: 5 | T10: 27
A11: 6 | B11: 27 | D11: 6 | E11: 48 | G11: 6 | H11: 44 | J11: 6 | K11: 39 | M11: 6 | N11: 45 | P11: 6 | Q11: 50 | S11: 6 | T11: 27
A12: 7 | B12: 27 | D12: 7 | E12: 50 | G12: 7 | H12: 46 | J12: 7 | K12: 41 | M12: 7 | N12: 47 | P12: 7 | Q12: 52 | S12: 7 | T12: 27
A13: 8 | B13: 27 | D13: 8 | E13: 52 | G13: 8 | H13: 47 | J13: 8 | K13: 43 | M13: 8 | N13: 50 | P13: 8 | Q13: 53 | S13: 8 | T13: 27
A14: 9 | B14: 27 | D14: 9 | E14: 54 | G14: 9 | H14: 50 | J14: 9 | K14: 44 | M14: 9 | N14: 51 | P14: 9 | Q14: 54 | S14: 9 | T14: 27
A15: 10 | B15: 27 | D15: 10 | E15: 56 | G15: 10 | H15: 52 | J15: 10 | K15: 45 | M15: 10 | N15: 52 | P15: 10 | Q15: 55 | S15: 10 | T15: 27
A16: 11 | B16: 27 | D16: 11 | E16: 58 | G16: 11 | H16: 52 | J16: 11 | K16: 48 | M16: 11 | N16: 53 | P16: 11 | Q16: 56 | S16: 11 | T16: 27
... A29: 24 | B29: 38 | D29: 24 | E29: 73 | G29: 24 | H29: 65 | J29: 24 | K29: 58 | M29: 24 | N29: 67 | P29: 24 | Q29: 67 | S29: 24 | T29: 41
A30: 25 | B30: 39 | G30: 25 | H30: 66 | J30: 25 | K30: 58 | M30: 25 | N30: 70 | P30: 25 | Q30: 67 | S30: 25 | T30: 42
A31: 26 | B31: 40 | G31: 26 | H31: 66 | J31: 26 | K31: 58 | M31: 26 | N31: 75 | P31: 26 | Q31: 67 | S31: 26 | T31: 43
A32: 27 | B32: 41 | G32: 27 | H32: 66 | J32: 27 | K32: 59 | M32: 27 | N32: 75 | P32: 27 | Q32: 67 | S32: 27 | T32: 44
A33: 28 | B33: 42 | G33: 28 | H33: 68 | J33: 28 | K33: 59 | M33: 28 | N33: 75 | P33: 28 | Q33: 69 | S33: 28 | T33: 45
A34: 29 | B34: 42 | G34: 29 | H34: 73 | J34: 29 | K34: 60 | M34: 29 | N34: 75 | P34: 29 | Q34: 69 | S34: 29 | T34: 46
A35: 30 | B35: 43 | G35: 30 | H35: 73 | J35: 30 | K35: 60 | M35: 30 | N35: 75 | P35: 30 | Q35: 69 | S35: 30 | T35: 46
A36: 31 | B36: 44 | G36: 31 | H36: 73 | J36: 31 | K36: 60 | M36: 31 | N36: 75 | P36: 31 | Q36: 71 | S36: 31 | T36: 46
A37: 32 | B37: 45 | G37: 32 | H37: 73 | J37: 32 | K37: 61 | M37: 32 | N37: 75 | P37: 32 | Q37: 75 | S37: 32 | T37: 47
A38: 33 | B38: 45 | G38: 33 | H38: 73 | J38: 33 | K38: 62 | M38: 33 | N38: 75 | P38: 33 | Q38: 75 | S38: 33 | T38: 48
A39: 34 | B39: 46 | G39: 34 | H39: 73 | J39: 34 | K39: 63 | P39: 34 | Q39: 75 | S39: 34 | T39: 49
A40: 35 | B40: 47 | G40: 35 | H40: 73 | J40: 35 | K40: 63 | P40: 35 | Q40: 75 | S40: 35 | T40: 49
A41: 36 | B41: 47 | G41: 36 | H41: 73 | J41: 36 | K41: 63 | P41: 36 | Q41: 75 | S41: 36 | T41: 50
A42: 37 | B42: 48 | J42: 37 | K42: 63 | S42: 37 | T42: 51
A43: 38 | B43: 49 | J43: 38 | K43: 65 | S43: 38 | T43: 51
A44: 39 | B44: 50 | J44: 39 | K44: 65 | S44: 39 | T44: 51
A45: 40 | B45: 50 | J45: 40 | K45: 67 | S45: 40 | T45: 51
A46: 41 | B46: 50 | J46: 41 | K46: 68 | S46: 41 | T46: 52
A47: 42 | B47: 50 | J47: 42 | K47: 69 | S47: 42 | T47: 52
A48: 43 | B48: 51 | J48: 43 | K48: 69 | S48: 43 | T48: 53
A49: 44 | B49: 51 | J49: 44 | K49: 69 | S49: 44 | T49: 53
A50: 45 | B50: 51 | J50: 45 | K50: 71 | S50: 45 | T50: 53
A51: 46 | B51: 51 | J51: 46 | K51: 71 | S51: 46 | T51: 54
A52: 47 | B52: 52 | J52: 47 | K52: 71 | S52: 47 | T52: 54
A53: 48 | B53: 52 | J53: 48 | K53: 71 | S53: 48 | T53: 54
...

Sheet Norma escolar (feminino)
A1: ESCOLAR FEMININO | D1: 3;11-19
A3: ESCORE TOTAL | D3: PERCEPÇÃO SOCIAL | G3: COGNIÇÃO SOCIAL | J3: COMUNICAÇÃO SOCIAL | M3: MOTIVAÇÃO SOCIAL | P3: PADRÕES RESTRITOS E REPETITIVOS | S3: COMUNICAÇÃO E INTERAÇÃO SOCIAL
A4: EB | B4: T | D4: EB | E4: T | G4: EB | H4: T | J4: EB | K4: T | M4: EB | N4: T | P4: EB | Q4: T | S4: EB | T4: T
A5: 0 | B5: 22 | D5: 0 | E5: 29 | G5: 0 | H5: 28 | J5: 0 | K5: 27 | M5: 0 | N5: 29 | P5: 0 | Q5: 34 | S5: 0 | T5: 22
A6: 1 | B6: 22 | D6: 1 | E6: 33 | G6: 1 | H6: 32 | J6: 1 | K6: 32 | M6: 1 | N6: 35 | P6: 1 | Q6: 41 | S6: 1 | T6: 22
A7: 2 | B7: 22 | D7: 2 | E7: 36 | G7: 2 | H7: 36 | J7: 2 | K7: 34 | M7: 2 | N7: 39 | P7: 2 | Q7: 45 | S7: 2 | T7: 22
A8: 3 | B8: 22 | D8: 3 | E8: 39 | G8: 3 | H8: 39 | J8: 3 | K8: 36 | M8: 3 | N8: 42 | P8: 3 | Q8: 48 | S8: 3 | T8: 22
A9: 4 | B9: 22 | D9: 4 | E9: 43 | G9: 4 | H9: 43 | J9: 4 | K9: 38 | M9: 4 | N9: 45 | P9: 4 | Q9: 51 | S9: 4 | T9: 22
A10: 5 | B10: 22 | D10: 5 | E10: 47 | G10: 5 | H10: 45 | J10: 5 | K10: 40 | M10: 5 | N10: 47 | P10: 5 | Q10: 52 | S10: 5 | T10: 22
A11: 6 | B11: 26 | D11: 6 | E11: 51 | G11: 6 | H11: 48 | J11: 6 | K11: 43 | M11: 6 | N11: 50 | P11: 6 | Q11: 54 | S11: 6 | T11: 26
A12: 7 | B12: 29 | D12: 7 | E12: 54 | G12: 7 | H12: 50 | J12: 7 | K12: 45 | M12: 7 | N12: 52 | P12: 7 | Q12: 55 | S12: 7 | T12: 29
A13: 8 | B13: 30 | D13: 8 | E13: 57 | G13: 8 | H13: 52 | J13: 8 | K13: 47 | M13: 8 | N13: 55 | P13: 8 | Q13: 57 | S13: 8 | T13: 31
A14: 9 | B14: 31 | D14: 9 | E14: 60 | G14: 9 | H14: 54 | J14: 9 | K14: 49 | M14: 9 | N14: 56 | P14: 9 | Q14: 59 | S14: 9 | T14: 32
A15: 10 | B15: 32 | D15: 10 | E15: 62 | G15: 10 | H15: 56 | J15: 10 | K15: 50 | M15: 10 | N15: 57 | P15: 10 | Q15: 60 | S15: 10 | T15: 32
A16: 11 | B16: 33 | D16: 11 | E16: 64 | G16: 11 | H16: 58 | J16: 11 | K16: 51 | M16: 11 | N16: 59 | P16: 11 | Q16: 61 | S16: 11 | T16: 33
... A29: 24 | B29: 44 | D29: 24 | E29: 78 | G29: 24 | H29: 72 | J29: 24 | K29: 63 | M29: 24 | N29: 74 | P29: 24 | Q29: 69 | S29: 24 | T29: 47
A30: 25 | B30: 45 | G30: 25 | H30: 72 | J30: 25 | K30: 63 | M30: 25 | N30: 74 | P30: 25 | Q30: 70 | S30: 25 | T30: 48
A31: 26 | B31: 46 | G31: 26 | H31: 74 | J31: 26 | K31: 64 | M31: 26 | N31: 74 | P31: 26 | Q31: 70 | S31: 26 | T31: 48
A32: 27 | B32: 47 | G32: 27 | H32: 74 | J32: 27 | K32: 64 | M32: 27 | N32: 74 | P32: 27 | Q32: 70 | S32: 27 | T32: 49
A33: 28 | B33: 47 | G33: 28 | H33: 74 | J33: 28 | K33: 65 | M33: 28 | N33: 78 | P33: 28 | Q33: 72 | S33: 28 | T33: 50
A34: 29 | B34: 48 | G34: 29 | H34: 74 | J34: 29 | K34: 66 | M34: 29 | N34: 78 | P34: 29 | Q34: 72 | S34: 29 | T34: 51
A35: 30 | B35: 49 | G35: 30 | H35: 74 | J35: 30 | K35: 66 | M35: 30 | N35: 78 | P35: 30 | Q35: 74 | S35: 30 | T35: 51
A36: 31 | B36: 49 | G36: 31 | H36: 74 | J36: 31 | K36: 66 | M36: 31 | N36: 78 | P36: 31 | Q36: 78 | S36: 31 | T36: 51
A37: 32 | B37: 50 | G37: 32 | H37: 74 | J37: 32 | K37: 67 | M37: 32 | N37: 78 | P37: 32 | Q37: 78 | S37: 32 | T37: 51
A38: 33 | B38: 50 | G38: 33 | H38: 78 | J38: 33 | K38: 67 | M38: 33 | N38: 78 | P38: 33 | Q38: 78 | S38: 33 | T38: 52
A39: 34 | B39: 51 | G39: 34 | H39: 78 | J39: 34 | K39: 68 | P39: 34 | Q39: 78 | S39: 34 | T39: 52
A40: 35 | B40: 51 | G40: 35 | H40: 78 | J40: 35 | K40: 68 | P40: 35 | Q40: 78 | S40: 35 | T40: 53
A41: 36 | B41: 51 | G41: 36 | H41: 78 | J41: 36 | K41: 68 | P41: 36 | Q41: 78 | S41: 36 | T41: 54
A42: 37 | B42: 52 | J42: 37 | K42: 69 | S42: 37 | T42: 55
A43: 38 | B43: 52 | J43: 38 | K43: 71 | S43: 38 | T43: 55
A44: 39 | B44: 53 | J44: 39 | K44: 71 | S44: 39 | T44: 56
A45: 40 | B45: 54 | J45: 40 | K45: 71 | S45: 40 | T45: 56
A46: 41 | B46: 54 | J46: 41 | K46: 71 | S46: 41 | T46: 56
A47: 42 | B47: 54 | J47: 42 | K47: 71 | S47: 42 | T47: 57
A48: 43 | B48: 54 | J48: 43 | K48: 74 | S48: 43 | T48: 57
A49: 44 | B49: 55 | J49: 44 | K49: 74 | S49: 44 | T49: 58
A50: 45 | B50: 55 | J50: 45 | K50: 74 | S50: 45 | T50: 58
A51: 46 | B51: 55 | J51: 46 | K51: 74 | S51: 46 | T51: 59
A52: 47 | B52: 56 | J52: 47 | K52: 74 | S52: 47 | T52: 59
A53: 48 | B53: 56 | J53: 48 | K53: 74 | S53: 48 | T53: 60
...

Sheet Norma adulto autorrelato
A1: ADULTO AUTORRELATO | D1: 18;11-74;11
A3: ESCORE TOTAL | D3: PERCEPÇÃO SOCIAL | G3: COGNIÇÃO SOCIAL | J3: COMUNICAÇÃO SOCIAL | M3: MOTIVAÇÃO SOCIAL | P3: PADRÕES RESTRITOS E REPETITIVOS | S3: COMUNICAÇÃO E INTERAÇÃO SOCIAL
A4: EB | B4: T | D4: EB | E4: T | G4: EB | H4: T | J4: EB | K4: T | M4: EB | N4: T | P4: EB | Q4: T | S4: EB | T4: T
A5: 0 | B5: 21 | D5: 0 | E5: 21 | G5: 0 | H5: 21 | J5: 0 | K5: 26 | M5: 0 | N5: 21 | P5: 0 | Q5: 23 | S5: 0 | T5: 23
A6: 1 | B6: 21 | D6: 1 | E6: 21 | G6: 1 | H6: 26 | J6: 1 | K6: 26 | M6: 1 | N6: 21 | P6: 1 | Q6: 31 | S6: 1 | T6: 23
A7: 2 | B7: 21 | D7: 2 | E7: 26 | G7: 2 | H7: 32 | J7: 2 | K7: 26 | M7: 2 | N7: 26 | P7: 2 | Q7: 37 | S7: 2 | T7: 23
A8: 3 | B8: 21 | D8: 3 | E8: 31 | G8: 3 | H8: 36 | J8: 3 | K8: 26 | M8: 3 | N8: 30 | P8: 3 | Q8: 41 | S8: 3 | T8: 23
A9: 4 | B9: 21 | D9: 4 | E9: 35 | G9: 4 | H9: 39 | J9: 4 | K9: 30 | M9: 4 | N9: 34 | P9: 4 | Q9: 44 | S9: 4 | T9: 23
A10: 5 | B10: 21 | D10: 5 | E10: 39 | G10: 5 | H10: 41 | J10: 5 | K10: 33 | M10: 5 | N10: 38 | P10: 5 | Q10: 46 | S10: 5 | T10: 23
A11: 6 | B11: 21 | D11: 6 | E11: 44 | G11: 6 | H11: 43 | J11: 6 | K11: 34 | M11: 6 | N11: 41 | P11: 6 | Q11: 48 | S11: 6 | T11: 23
A12: 7 | B12: 21 | D12: 7 | E12: 48 | G12: 7 | H12: 45 | J12: 7 | K12: 36 | M12: 7 | N12: 43 | P12: 7 | Q12: 50 | S12: 7 | T12: 23
A13: 8 | B13: 21 | D13: 8 | E13: 52 | G13: 8 | H13: 47 | J13: 8 | K13: 39 | M13: 8 | N13: 47 | P13: 8 | Q13: 52 | S13: 8 | T13: 23
A14: 9 | B14: 21 | D14: 9 | E14: 55 | G14: 9 | H14: 49 | J14: 9 | K14: 40 | M14: 9 | N14: 49 | P14: 9 | Q14: 54 | S14: 9 | T14: 23
A15: 10 | B15: 21 | D15: 10 | E15: 59 | G15: 10 | H15: 51 | J15: 10 | K15: 42 | M15: 10 | N15: 51 | P15: 10 | Q15: 56 | S15: 10 | T15: 23
A16: 11 | B16: 21 | D16: 11 | E16: 63 | G16: 11 | H16: 53 | J16: 11 | K16: 44 | M16: 11 | N16: 53 | P16: 11 | Q16: 58 | S16: 11 | T16: 23
... A29: 24 | B29: 36 | D29: 24 | E29: 79 | G29: 24 | H29: 72 | J29: 24 | K29: 58 | M29: 24 | N29: 74 | P29: 24 | Q29: 69 | S29: 24 | T29: 38
A30: 25 | B30: 36 | G30: 25 | H30: 74 | J30: 25 | K30: 59 | M30: 25 | N30: 75 | P30: 25 | Q30: 71 | S30: 25 | T30: 39
A31: 26 | B31: 37 | G31: 26 | H31: 74 | J31: 26 | K31: 60 | M31: 26 | N31: 75 | P31: 26 | Q31: 73 | S31: 26 | T31: 40
A32: 27 | B32: 38 | G32: 27 | H32: 74 | J32: 27 | K32: 61 | M32: 27 | N32: 75 | P32: 27 | Q32: 75 | S32: 27 | T32: 40
A33: 28 | B33: 39 | G33: 28 | H33: 74 | J33: 28 | K33: 61 | M33: 28 | N33: 75 | P33: 28 | Q33: 75 | S33: 28 | T33: 41
A34: 29 | B34: 39 | G34: 29 | H34: 74 | J34: 29 | K34: 62 | M34: 29 | N34: 79 | P34: 29 | Q34: 75 | S34: 29 | T34: 41
A35: 30 | B35: 40 | G35: 30 | H35: 74 | J35: 30 | K35: 63 | M35: 30 | N35: 79 | P35: 30 | Q35: 75 | S35: 30 | T35: 42
A36: 31 | B36: 40 | G36: 31 | H36: 75 | J36: 31 | K36: 63 | M36: 31 | N36: 79 | P36: 31 | Q36: 75 | S36: 31 | T36: 43
A37: 32 | B37: 41 | G37: 32 | H37: 75 | J37: 32 | K37: 63 | M37: 32 | N37: 79 | P37: 32 | Q37: 79 | S37: 32 | T37: 43
A38: 33 | B38: 42 | G38: 33 | H38: 75 | J38: 33 | K38: 64 | M38: 33 | N38: 79 | P38: 33 | Q38: 79 | S38: 33 | T38: 44
A39: 34 | B39: 42 | G39: 34 | H39: 75 | J39: 34 | K39: 65 | P39: 34 | Q39: 79 | S39: 34 | T39: 44
A40: 35 | B40: 43 | G40: 35 | H40: 75 | J40: 35 | K40: 66 | P40: 35 | Q40: 79 | S40: 35 | T40: 45
A41: 36 | B41: 43 | G41: 36 | H41: 79 | J41: 36 | K41: 67 | P41: 36 | Q41: 79 | S41: 36 | T41: 46
A42: 37 | B42: 43 | J42: 37 | K42: 68 | S42: 37 | T42: 47
A43: 38 | B43: 44 | J43: 38 | K43: 69 | S43: 38 | T43: 47
A44: 39 | B44: 44 | J44: 39 | K44: 70 | S44: 39 | T44: 48
A45: 40 | B45: 45 | J45: 40 | K45: 70 | S45: 40 | T45: 48
A46: 41 | B46: 45 | J46: 41 | K46: 70 | S46: 41 | T46: 48
A47: 42 | B47: 46 | J47: 42 | K47: 71 | S47: 42 | T47: 49
A48: 43 | B48: 47 | J48: 43 | K48: 71 | S48: 43 | T48: 49
A49: 44 | B49: 47 | J49: 44 | K49: 72 | S49: 44 | T49: 50
A50: 45 | B50: 47 | J50: 45 | K50: 72 | S50: 45 | T50: 50
A51: 46 | B51: 48 | J51: 46 | K51: 74 | S51: 46 | T51: 51
A52: 47 | B52: 48 | J52: 47 | K52: 74 | S52: 47 | T52: 52
A53: 48 | B53: 48 | J53: 48 | K53: 74 | S53: 48 | T53: 52
...

Sheet Norma adulto hetero
A1: ADULTO HETERO | D1: 18;11-66;0
A3: ESCORE TOTAL | D3: PERCEPÇÃO SOCIAL | G3: COGNIÇÃO SOCIAL | J3: COMUNICAÇÃO SOCIAL | M3: MOTIVAÇÃO SOCIAL | P3: PADRÕES RESTRITOS E REPETITIVOS | S3: COMUNICAÇÃO E INTERAÇÃO SOCIAL
A4: EB | B4: T | D4: EB | E4: T | G4: EB | H4: T | J4: EB | K4: T | M4: EB | N4: T | P4: EB | Q4: T | S4: EB | T4: T
A5: 0 | B5: 23 | D5: 0 | E5: 25 | G5: 0 | H5: 27 | J5: 0 | K5: 25 | M5: 0 | N5: 23 | P5: 0 | Q5: 34 | S5: 0 | T5: 25
A6: 1 | B6: 23 | D6: 1 | E6: 29 | G6: 1 | H6: 34 | J6: 1 | K6: 32 | M6: 1 | N6: 29 | P6: 1 | Q6: 40 | S6: 1 | T6: 25
A7: 2 | B7: 23 | D7: 2 | E7: 36 | G7: 2 | H7: 38 | J7: 2 | K7: 36 | M7: 2 | N7: 33 | P7: 2 | Q7: 44 | S7: 2 | T7: 25
A8: 3 | B8: 23 | D8: 3 | E8: 41 | G8: 3 | H8: 40 | J8: 3 | K8: 38 | M8: 3 | N8: 39 | P8: 3 | Q8: 46 | S8: 3 | T8: 25
A9: 4 | B9: 23 | D9: 4 | E9: 45 | G9: 4 | H9: 41 | J9: 4 | K9: 40 | M9: 4 | N9: 43 | P9: 4 | Q9: 48 | S9: 4 | T9: 25
A10: 5 | B10: 23 | D10: 5 | E10: 48 | G10: 5 | H10: 44 | J10: 5 | K10: 42 | M10: 5 | N10: 45 | P10: 5 | Q10: 50 | S10: 5 | T10: 25
A11: 6 | B11: 23 | D11: 6 | E11: 51 | G11: 6 | H11: 47 | J11: 6 | K11: 43 | M11: 6 | N11: 47 | P11: 6 | Q11: 51 | S11: 6 | T11: 25
A12: 7 | B12: 29 | D12: 7 | E12: 54 | G12: 7 | H12: 48 | J12: 7 | K12: 44 | M12: 7 | N12: 49 | P12: 7 | Q12: 53 | S12: 7 | T12: 30
A13: 8 | B13: 31 | D13: 8 | E13: 56 | G13: 8 | H13: 50 | J13: 8 | K13: 46 | M13: 8 | N13: 51 | P13: 8 | Q13: 54 | S13: 8 | T13: 32
A14: 9 | B14: 31 | D14: 9 | E14: 58 | G14: 9 | H14: 51 | J14: 9 | K14: 46 | M14: 9 | N14: 53 | P14: 9 | Q14: 55 | S14: 9 | T14: 33
A15: 10 | B15: 33 | D15: 10 | E15: 62 | G15: 10 | H15: 52 | J15: 10 | K15: 47 | M15: 10 | N15: 54 | P15: 10 | Q15: 56 | S15: 10 | T15: 34
A16: 11 | B16: 35 | D16: 11 | E16: 64 | G16: 11 | H16: 53 | J16: 11 | K16: 47 | M16: 11 | N16: 55 | P16: 11 | Q16: 57 | S16: 11 | T16: 36
... A29: 24 | B29: 45 | D29: 24 | E29: 75 | G29: 24 | H29: 66 | J29: 24 | K29: 58 | M29: 24 | N29: 69 | P29: 24 | Q29: 66 | S29: 24 | T29: 45
A30: 25 | B30: 45 | G30: 25 | H30: 66 | J30: 25 | K30: 59 | M30: 25 | N30: 69 | P30: 25 | Q30: 69 | S30: 25 | T30: 45
A31: 26 | B31: 45 | G31: 26 | H31: 68 | J31: 26 | K31: 59 | M31: 26 | N31: 69 | P31: 26 | Q31: 69 | S31: 26 | T31: 46
A32: 27 | B32: 45 | G32: 27 | H32: 68 | J32: 27 | K32: 59 | M32: 27 | N32: 69 | P32: 27 | Q32: 73 | S32: 27 | T32: 46
A33: 28 | B33: 46 | G33: 28 | H33: 69 | J33: 28 | K33: 60 | M33: 28 | N33: 71 | P33: 28 | Q33: 77 | S33: 28 | T33: 47
A34: 29 | B34: 46 | G34: 29 | H34: 70 | J34: 29 | K34: 61 | M34: 29 | N34: 71 | P34: 29 | Q34: 77 | S34: 29 | T34: 47
A35: 30 | B35: 46 | G35: 30 | H35: 72 | J35: 30 | K35: 62 | M35: 30 | N35: 75 | P35: 30 | Q35: 77 | S35: 30 | T35: 48
A36: 31 | B36: 47 | G36: 31 | H36: 72 | J36: 31 | K36: 62 | M36: 31 | N36: 75 | P36: 31 | Q36: 77 | S36: 31 | T36: 48
A37: 32 | B37: 47 | G37: 32 | H37: 72 | J37: 32 | K37: 62 | M37: 32 | N37: 75 | P37: 32 | Q37: 77 | S37: 32 | T37: 48
A38: 33 | B38: 48 | G38: 33 | H38: 72 | J38: 33 | K38: 63 | M38: 33 | N38: 75 | P38: 33 | Q38: 77 | S38: 33 | T38: 48
A39: 34 | B39: 48 | G39: 34 | H39: 72 | J39: 34 | K39: 63 | P39: 34 | Q39: 77 | S39: 34 | T39: 48
A40: 35 | B40: 48 | G40: 35 | H40: 77 | J40: 35 | K40: 63 | P40: 35 | Q40: 77 | S40: 35 | T40: 49
A41: 36 | B41: 48 | G41: 36 | H41: 77 | J41: 36 | K41: 63 | P41: 36 | Q41: 77 | S41: 36 | T41: 49
A42: 37 | B42: 48 | J42: 37 | K42: 64 | S42: 37 | T42: 50
A43: 38 | B43: 48 | J43: 38 | K43: 64 | S43: 38 | T43: 50
A44: 39 | B44: 49 | J44: 39 | K44: 65 | S44: 39 | T44: 51
A45: 40 | B45: 49 | J45: 40 | K45: 65 | S45: 40 | T45: 51
A46: 41 | B46: 49 | J46: 41 | K46: 66 | S46: 41 | T46: 52
A47: 42 | B47: 50 | J47: 42 | K47: 67 | S47: 42 | T47: 53
A48: 43 | B48: 50 | J48: 43 | K48: 67 | S48: 43 | T48: 53
A49: 44 | B49: 50 | J49: 44 | K49: 68 | S49: 44 | T49: 54
A50: 45 | B50: 50 | J50: 45 | K50: 69 | S50: 45 | T50: 54
A51: 46 | B51: 51 | J51: 46 | K51: 69 | S51: 46 | T51: 55
A52: 47 | B52: 52 | J52: 47 | K52: 69 | S52: 47 | T52: 55
A53: 48 | B53: 52 | J53: 48 | K53: 69 | S53: 48 | T53: 55
...
